{
  "affected_release": null,
  "package_state": [
    {
      "product_name": "Red Hat Enterprise Linux 3",
      "fix_state": "Affected",
      "package_name": "python",
      "cpe": "cpe:/o:redhat:enterprise_linux:3"
    },
    {
      "product_name": "Red Hat Enterprise Linux 4",
      "fix_state": "Affected",
      "package_name": "python",
      "cpe": "cpe:/o:redhat:enterprise_linux:4"
    },
    {
      "product_name": "Red Hat Enterprise Linux 5",
      "fix_state": "Affected",
      "package_name": "python",
      "cpe": "cpe:/o:redhat:enterprise_linux:5"
    },
    {
      "product_name": "Red Hat Enterprise Linux 6",
      "fix_state": "Affected",
      "package_name": "python",
      "cpe": "cpe:/o:redhat:enterprise_linux:6"
    }
  ],
  "threat_severity": "Low",
  "public_date": "2010-09-09T00:00:00Z",
  "bugzilla": {
    "description": "CVE-2010-3492 python accept() implementation in async core is broken",
    "id": "638330",
    "url": "https://bugzilla.redhat.com/show_bug.cgi?id=638330"
  },
  "cvss": {
    "cvss_base_score": "5.0",
    "cvss_scoring_vector": "AV:N/AC:L/Au:N/C:N/I:N/A:P",
    "status": "draft"
  },
  "cvss3": {
    "cvss3_base_score": "",
    "cvss3_scoring_vector": "",
    "status": ""
  },
  "iava": "",
  "cwe": "",
  "statement": "This issue affects the version of the python package as shipped with Red Hat Enterprise Linux 4, 5, and 6. Due to the nature of this flaw, it cannot be fixed in the python language, but must be addressed in each module which calls accept().",
  "acknowledgement": "",
  "name": "CVE-2010-3492",
  "document_distribution": "",
  "details": [
    "The asyncore module in Python before 3.2 does not properly handle unsuccessful calls to the accept function, and does not have accompanying documentation describing how daemon applications should handle unsuccessful calls to the accept function, which makes it easier for remote attackers to conduct denial of service attacks that terminate these applications via network connections."
  ],
  "references": [
    "https://www.cve.org/CVERecord?id=CVE-2010-3492\nhttps://nvd.nist.gov/vuln/detail/CVE-2010-3492"
  ]
}