{
  "affected_release": null,
  "package_state": [
    {
      "product_name": "Red Hat Enterprise Linux 6",
      "fix_state": "Out of support scope",
      "package_name": "scipy",
      "cpe": "cpe:/o:redhat:enterprise_linux:6"
    },
    {
      "product_name": "Red Hat Enterprise Linux 7",
      "fix_state": "Out of support scope",
      "package_name": "scipy",
      "cpe": "cpe:/o:redhat:enterprise_linux:7"
    },
    {
      "product_name": "Red Hat Enterprise Linux 8",
      "fix_state": "Affected",
      "package_name": "python27:2.7/scipy",
      "cpe": "cpe:/o:redhat:enterprise_linux:8"
    },
    {
      "product_name": "Red Hat Enterprise Linux 8",
      "fix_state": "Affected",
      "package_name": "python3.11-scipy",
      "cpe": "cpe:/o:redhat:enterprise_linux:8"
    },
    {
      "product_name": "Red Hat Enterprise Linux 8",
      "fix_state": "Affected",
      "package_name": "python36:3.6/scipy",
      "cpe": "cpe:/o:redhat:enterprise_linux:8"
    },
    {
      "product_name": "Red Hat Enterprise Linux 8",
      "fix_state": "Affected",
      "package_name": "python39:3.9/scipy",
      "cpe": "cpe:/o:redhat:enterprise_linux:8"
    },
    {
      "product_name": "Red Hat Enterprise Linux 9",
      "fix_state": "Affected",
      "package_name": "python3.11-scipy",
      "cpe": "cpe:/o:redhat:enterprise_linux:9"
    },
    {
      "product_name": "Red Hat Enterprise Linux 9",
      "fix_state": "Affected",
      "package_name": "scipy",
      "cpe": "cpe:/o:redhat:enterprise_linux:9"
    },
    {
      "product_name": "Red Hat OpenShift Container Platform 4",
      "fix_state": "Affected",
      "package_name": "google-benchmark",
      "cpe": "cpe:/a:redhat:openshift:4"
    },
    {
      "product_name": "Red Hat OpenShift Container Platform 4",
      "fix_state": "Not affected",
      "package_name": "python-sortedcontainers",
      "cpe": "cpe:/a:redhat:openshift:4"
    },
    {
      "product_name": "Red Hat Software Collections",
      "fix_state": "Affected",
      "package_name": "rh-python38-scipy",
      "cpe": "cpe:/a:redhat:rhel_software_collections:3"
    }
  ],
  "threat_severity": "Moderate",
  "public_date": "2023-07-06T00:00:00Z",
  "bugzilla": {
    "description": "use-after-free in Py_FindObjects() function",
    "id": "2221034",
    "url": "https://bugzilla.redhat.com/show_bug.cgi?id=2221034"
  },
  "cvss": {
    "cvss_base_score": "",
    "cvss_scoring_vector": "",
    "status": ""
  },
  "cvss3": {
    "cvss3_base_score": "7.0",
    "cvss3_scoring_vector": "CVSS:3.1/AV:N/AC:H/PR:N/UI:N/S:U/C:L/I:L/A:H",
    "status": "draft"
  },
  "iava": "",
  "cwe": "CWE-416",
  "statement": "This CVE is disputed as per upstream - https://github.com/scipy/scipy/issues/14713#issuecomment-1629468565",
  "acknowledgement": "",
  "name": "CVE-2023-29824",
  "document_distribution": "",
  "details": [
    "** DISPUTED ** A use-after-free issue was discovered in Py_FindObjects() function in SciPy versions prior to 1.8.0. NOTE: the vendor and discoverer indicate that this is not a security issue."
  ],
  "references": [
    "https://www.cve.org/CVERecord?id=CVE-2023-29824\nhttps://nvd.nist.gov/vuln/detail/CVE-2023-29824\nhttp://www.square16.org/achievement/cve-2023-29824/\nhttps://github.com/scipy/scipy/issues/14713#issuecomment-1629468565"
  ]
}