{
  "affected_release": null,
  "package_state": [
    {
      "product_name": "Red Hat Enterprise Linux 6",
      "fix_state": "Under investigation",
      "package_name": "python-configobj",
      "cpe": "cpe:/o:redhat:enterprise_linux:6"
    },
    {
      "product_name": "Red Hat Enterprise Linux 7",
      "fix_state": "Under investigation",
      "package_name": "python-configobj",
      "cpe": "cpe:/o:redhat:enterprise_linux:7"
    },
    {
      "product_name": "Red Hat Enterprise Linux 8",
      "fix_state": "Under investigation",
      "package_name": "python-configobj",
      "cpe": "cpe:/o:redhat:enterprise_linux:8"
    },
    {
      "product_name": "Red Hat Enterprise Linux 9",
      "fix_state": "Under investigation",
      "package_name": "python-configobj",
      "cpe": "cpe:/o:redhat:enterprise_linux:9"
    },
    {
      "product_name": "Red Hat OpenShift Dev Spaces",
      "fix_state": "Under investigation",
      "package_name": "devspaces-udi-container",
      "cpe": "cpe:/a:redhat:openshift_devspaces:3::el8"
    }
  ],
  "threat_severity": "Low",
  "public_date": "2023-04-03T00:00:00Z",
  "bugzilla": {
    "description": "CVE-2023-26112 python-configobj: Regular expression denial of service exists in ./src/configobj/validate.py",
    "id": "2184017",
    "url": "https://bugzilla.redhat.com/show_bug.cgi?id=2184017"
  },
  "cvss": {
    "cvss_base_score": "",
    "cvss_scoring_vector": "",
    "status": ""
  },
  "cvss3": {
    "cvss3_base_score": "3.7",
    "cvss3_scoring_vector": "CVSS:3.1/AV:N/AC:H/PR:N/UI:N/S:U/C:N/I:N/A:L",
    "status": "draft"
  },
  "iava": "",
  "cwe": "CWE-1333",
  "statement": "",
  "acknowledgement": "",
  "name": "CVE-2023-26112",
  "document_distribution": "",
  "details": [
    "All versions of the package configobj are vulnerable to Regular Expression Denial of Service (ReDoS) via the validate function, using (.+?)\\((.*)\\). **Note:** This is only exploitable in the case of a developer, putting the offending value in a server side configuration file."
  ],
  "references": [
    "https://www.cve.org/CVERecord?id=CVE-2023-26112\nhttps://nvd.nist.gov/vuln/detail/CVE-2023-26112"
  ]
}